/home/caoyiwen/anaconda3/envs/segtest/lib/python3.8/site-packages/torch/distributed/launch.py:178: FutureWarning: The module torch.distributed.launch is deprecated
and will be removed in future. Use torchrun.
Note that --use_env is set by default in torchrun.
If your script expects `--local_rank` argument to be set, please
change it to read from `os.environ['LOCAL_RANK']` instead. See 
https://pytorch.org/docs/stable/distributed.html#launch-utility for 
further instructions

  warnings.warn(
WARNING:torch.distributed.run:
*****************************************
Setting OMP_NUM_THREADS environment variable for each process to be 1 in default, to avoid your system being overloaded, please further tune the variable for optimal performance in your application as needed. 
*****************************************
/home/caoyiwen/anaconda3/envs/segtest/lib/python3.8/site-packages/apex/pyprof/__init__.py:5: FutureWarning: pyprof will be removed by the end of June, 2022
  warnings.warn("pyprof will be removed by the end of June, 2022", FutureWarning)
/home/caoyiwen/anaconda3/envs/segtest/lib/python3.8/site-packages/apex/pyprof/__init__.py:5: FutureWarning: pyprof will be removed by the end of June, 2022
  warnings.warn("pyprof will be removed by the end of June, 2022", FutureWarning)
/home/caoyiwen/anaconda3/envs/segtest/lib/python3.8/site-packages/apex/pyprof/__init__.py:5: FutureWarning: pyprof will be removed by the end of June, 2022
  warnings.warn("pyprof will be removed by the end of June, 2022", FutureWarning)
/home/caoyiwen/anaconda3/envs/segtest/lib/python3.8/site-packages/apex/pyprof/__init__.py:5: FutureWarning: pyprof will be removed by the end of June, 2022
  warnings.warn("pyprof will be removed by the end of June, 2022", FutureWarning)
/home/caoyiwen/anaconda3/envs/segtest/lib/python3.8/site-packages/apex/pyprof/__init__.py:5: FutureWarning: pyprof will be removed by the end of June, 2022
  warnings.warn("pyprof will be removed by the end of June, 2022", FutureWarning)
/home/caoyiwen/anaconda3/envs/segtest/lib/python3.8/site-packages/apex/pyprof/__init__.py:5: FutureWarning: pyprof will be removed by the end of June, 2022
  warnings.warn("pyprof will be removed by the end of June, 2022", FutureWarning)
/home/caoyiwen/anaconda3/envs/segtest/lib/python3.8/site-packages/apex/pyprof/__init__.py:5: FutureWarning: pyprof will be removed by the end of June, 2022
  warnings.warn("pyprof will be removed by the end of June, 2022", FutureWarning)
/home/caoyiwen/anaconda3/envs/segtest/lib/python3.8/site-packages/apex/pyprof/__init__.py:5: FutureWarning: pyprof will be removed by the end of June, 2022
  warnings.warn("pyprof will be removed by the end of June, 2022", FutureWarning)
Total world size:  8
Total world size:  8
Total world size:  8
Total world size:  8
Total world size:  8
Total world size:  8
Total world size:  8
Total world size:  8
My Rank: 4
My Rank: 0
My Rank: 3
My Rank: 2
My Rank: 6
My Rank: 7
My Rank: 1
My Rank: 5
Traceback (most recent call last):
  File "train.py", line 434, in <module>
    main()
  File "train.py", line 185, in main
    train_loader, val_loader, train_obj = datasets.setup_loaders(args)
  File "/home/caoyiwen/slns/PFNets/datasets/__init__.py", line 160, in setup_loaders
    train_set = args.dataset_cls.ISAIDDataset(
  File "/home/caoyiwen/slns/PFNets/datasets/iSAID.py", line 81, in __init__
    self.data_tokens = make_dataset(quality, mode, hardnm)
  File "/home/caoyiwen/slns/PFNets/datasets/iSAID.py", line 44, in make_dataset
    c_tokens = os.listdir(image_path)
FileNotFoundError: [Errno 2] No such file or directory: './data/iSAID/train/images'
Traceback (most recent call last):
  File "train.py", line 434, in <module>
    main()
  File "train.py", line 185, in main
    train_loader, val_loader, train_obj = datasets.setup_loaders(args)
  File "/home/caoyiwen/slns/PFNets/datasets/__init__.py", line 160, in setup_loaders
    train_set = args.dataset_cls.ISAIDDataset(
  File "/home/caoyiwen/slns/PFNets/datasets/iSAID.py", line 81, in __init__
Traceback (most recent call last):
  File "train.py", line 434, in <module>
    self.data_tokens = make_dataset(quality, mode, hardnm)
  File "/home/caoyiwen/slns/PFNets/datasets/iSAID.py", line 44, in make_dataset
    c_tokens = os.listdir(image_path)
FileNotFoundError: [Errno 2] No such file or directory: './data/iSAID/train/images'
Traceback (most recent call last):
  File "train.py", line 434, in <module>
    main()
  File "train.py", line 185, in main
    train_loader, val_loader, train_obj = datasets.setup_loaders(args)
  File "/home/caoyiwen/slns/PFNets/datasets/__init__.py", line 160, in setup_loaders
    main()
  File "train.py", line 185, in main
    train_set = args.dataset_cls.ISAIDDataset(
  File "/home/caoyiwen/slns/PFNets/datasets/iSAID.py", line 81, in __init__
    train_loader, val_loader, train_obj = datasets.setup_loaders(args)
  File "/home/caoyiwen/slns/PFNets/datasets/__init__.py", line 160, in setup_loaders
    self.data_tokens = make_dataset(quality, mode, hardnm)
  File "/home/caoyiwen/slns/PFNets/datasets/iSAID.py", line 44, in make_dataset
    c_tokens = os.listdir(image_path)
FileNotFoundError    : train_set = args.dataset_cls.ISAIDDataset([Errno 2] No such file or directory: './data/iSAID/train/images'

  File "/home/caoyiwen/slns/PFNets/datasets/iSAID.py", line 81, in __init__
    self.data_tokens = make_dataset(quality, mode, hardnm)
  File "/home/caoyiwen/slns/PFNets/datasets/iSAID.py", line 44, in make_dataset
    c_tokens = os.listdir(image_path)
FileNotFoundError: [Errno 2] No such file or directory: './data/iSAID/train/images'
Traceback (most recent call last):
  File "train.py", line 434, in <module>
Traceback (most recent call last):
  File "train.py", line 434, in <module>
    main()
  File "train.py", line 185, in main
    main()
  File "train.py", line 185, in main
Logging : ./iSAID//r50/iSAI-network.pointflow_resnet_with_max_avg_pool.DeepR50_PF_maxavg_deeply_apex_T_cup_cs_dataset_iSAID_edge_points_128_ew_jepf_maxpool_size_14_ohem_T_poly_exp_0.9/log_2022_06_10_08_22_08_rank_0.log
        train_loader, val_loader, train_obj = datasets.setup_loaders(args)train_loader, val_loader, train_obj = datasets.setup_loaders(args)

  File "/home/caoyiwen/slns/PFNets/datasets/__init__.py", line 160, in setup_loaders
  File "/home/caoyiwen/slns/PFNets/datasets/__init__.py", line 160, in setup_loaders
    train_set = args.dataset_cls.ISAIDDataset(
      File "/home/caoyiwen/slns/PFNets/datasets/iSAID.py", line 81, in __init__
train_set = args.dataset_cls.ISAIDDataset(
  File "/home/caoyiwen/slns/PFNets/datasets/iSAID.py", line 81, in __init__
    self.data_tokens = make_dataset(quality, mode, hardnm)
  File "/home/caoyiwen/slns/PFNets/datasets/iSAID.py", line 44, in make_dataset
    self.data_tokens = make_dataset(quality, mode, hardnm)
  File "/home/caoyiwen/slns/PFNets/datasets/iSAID.py", line 44, in make_dataset
    c_tokens = os.listdir(image_path)
FileNotFoundError: [Errno 2] No such file or directory: './data/iSAID/train/images'
    c_tokens = os.listdir(image_path)
Traceback (most recent call last):
FileNotFoundError  File "train.py", line 434, in <module>
: [Errno 2] No such file or directory: './data/iSAID/train/images'
    main()
  File "train.py", line 185, in main
    train_loader, val_loader, train_obj = datasets.setup_loaders(args)
  File "/home/caoyiwen/slns/PFNets/datasets/__init__.py", line 160, in setup_loaders
    train_set = args.dataset_cls.ISAIDDataset(
  File "/home/caoyiwen/slns/PFNets/datasets/iSAID.py", line 81, in __init__
    self.data_tokens = make_dataset(quality, mode, hardnm)
  File "/home/caoyiwen/slns/PFNets/datasets/iSAID.py", line 44, in make_dataset
    c_tokens = os.listdir(image_path)
FileNotFoundError: [Errno 2] No such file or directory: './data/iSAID/train/images'
Traceback (most recent call last):
  File "train.py", line 434, in <module>
    main()
  File "train.py", line 185, in main
    train_loader, val_loader, train_obj = datasets.setup_loaders(args)
  File "/home/caoyiwen/slns/PFNets/datasets/__init__.py", line 160, in setup_loaders
    train_set = args.dataset_cls.ISAIDDataset(
  File "/home/caoyiwen/slns/PFNets/datasets/iSAID.py", line 81, in __init__
    self.data_tokens = make_dataset(quality, mode, hardnm)
  File "/home/caoyiwen/slns/PFNets/datasets/iSAID.py", line 44, in make_dataset
    c_tokens = os.listdir(image_path)
FileNotFoundError: [Errno 2] No such file or directory: './data/iSAID/train/images'
ERROR:torch.distributed.elastic.multiprocessing.api:failed (exitcode: 1) local_rank: 0 (pid: 44602) of binary: /home/caoyiwen/anaconda3/envs/segtest/bin/python
Traceback (most recent call last):
  File "/home/caoyiwen/anaconda3/envs/segtest/lib/python3.8/runpy.py", line 194, in _run_module_as_main
    return _run_code(code, main_globals, None,
  File "/home/caoyiwen/anaconda3/envs/segtest/lib/python3.8/runpy.py", line 87, in _run_code
    exec(code, run_globals)
  File "/home/caoyiwen/anaconda3/envs/segtest/lib/python3.8/site-packages/torch/distributed/launch.py", line 193, in <module>
    main()
  File "/home/caoyiwen/anaconda3/envs/segtest/lib/python3.8/site-packages/torch/distributed/launch.py", line 189, in main
    launch(args)
  File "/home/caoyiwen/anaconda3/envs/segtest/lib/python3.8/site-packages/torch/distributed/launch.py", line 174, in launch
    run(args)
  File "/home/caoyiwen/anaconda3/envs/segtest/lib/python3.8/site-packages/torch/distributed/run.py", line 715, in run
    elastic_launch(
  File "/home/caoyiwen/anaconda3/envs/segtest/lib/python3.8/site-packages/torch/distributed/launcher/api.py", line 131, in __call__
    return launch_agent(self._config, self._entrypoint, list(args))
  File "/home/caoyiwen/anaconda3/envs/segtest/lib/python3.8/site-packages/torch/distributed/launcher/api.py", line 245, in launch_agent
    raise ChildFailedError(
torch.distributed.elastic.multiprocessing.errors.ChildFailedError: 
============================================================
train.py FAILED
------------------------------------------------------------
Failures:
[1]:
  time      : 2022-06-10_08:22:10
  host      : prui
  rank      : 1 (local_rank: 1)
  exitcode  : 1 (pid: 44603)
  error_file: <N/A>
  traceback : To enable traceback see: https://pytorch.org/docs/stable/elastic/errors.html
[2]:
  time      : 2022-06-10_08:22:10
  host      : prui
  rank      : 2 (local_rank: 2)
  exitcode  : 1 (pid: 44605)
  error_file: <N/A>
  traceback : To enable traceback see: https://pytorch.org/docs/stable/elastic/errors.html
[3]:
  time      : 2022-06-10_08:22:10
  host      : prui
  rank      : 3 (local_rank: 3)
  exitcode  : 1 (pid: 44607)
  error_file: <N/A>
  traceback : To enable traceback see: https://pytorch.org/docs/stable/elastic/errors.html
[4]:
  time      : 2022-06-10_08:22:10
  host      : prui
  rank      : 4 (local_rank: 4)
  exitcode  : 1 (pid: 44608)
  error_file: <N/A>
  traceback : To enable traceback see: https://pytorch.org/docs/stable/elastic/errors.html
[5]:
  time      : 2022-06-10_08:22:10
  host      : prui
  rank      : 5 (local_rank: 5)
  exitcode  : 1 (pid: 44609)
  error_file: <N/A>
  traceback : To enable traceback see: https://pytorch.org/docs/stable/elastic/errors.html
[6]:
  time      : 2022-06-10_08:22:10
  host      : prui
  rank      : 6 (local_rank: 6)
  exitcode  : 1 (pid: 44610)
  error_file: <N/A>
  traceback : To enable traceback see: https://pytorch.org/docs/stable/elastic/errors.html
[7]:
  time      : 2022-06-10_08:22:10
  host      : prui
  rank      : 7 (local_rank: 7)
  exitcode  : 1 (pid: 44611)
  error_file: <N/A>
  traceback : To enable traceback see: https://pytorch.org/docs/stable/elastic/errors.html
------------------------------------------------------------
Root Cause (first observed failure):
[0]:
  time      : 2022-06-10_08:22:10
  host      : prui
  rank      : 0 (local_rank: 0)
  exitcode  : 1 (pid: 44602)
  error_file: <N/A>
  traceback : To enable traceback see: https://pytorch.org/docs/stable/elastic/errors.html
============================================================
